[13:24:55] [34mINFO    [39m Waiting for tasks[33m...[39m                                                                                                     ]8;id=883794;file://C:\Users\DELL\AppData\Roaming\Python\Python38\site-packages\openfl\component\collaborator\collaborator.py\collaborator.py]8;;\:]8;id=805635;file://C:\Users\DELL\AppData\Roaming\Python\Python38\site-packages\openfl\component\collaborator\collaborator.py#210\210]8;;\
           [34mINFO    [39m Received the following tasks: [1m[[22mname: [32m"1_train"[39m                                                                           ]8;id=844151;file://C:\Users\DELL\AppData\Roaming\Python\Python38\site-packages\openfl\component\collaborator\collaborator.py\collaborator.py]8;;\:]8;id=330776;file://C:\Users\DELL\AppData\Roaming\Python\Python38\site-packages\openfl\component\collaborator\collaborator.py#172\172]8;;\
                    , name: [32m"2_weak_learners_validate"
                    , name: [32m"3_adaboost_update"
                    , name: [32m"4_adaboost_validate"
                    [1m]
           [34mINFO    [39m Using Interactive Python API                                                                                             ]8;id=988712;file://C:\Users\DELL\AppData\Roaming\Python\Python38\site-packages\openfl\component\collaborator\collaborator.py\collaborator.py]8;;\:]8;id=594731;file://C:\Users\DELL\AppData\Roaming\Python\Python38\site-packages\openfl\component\collaborator\collaborator.py#269\269]8;;\
Train Min times :  8
Train Max times :  285
Train Min times_1 : 8
Train Max times_1 : 235
[13:24:56] METRIC   Round [1m0[22m, collaborator envoy_1 is sending metric for task 1_train: Corcondance-index     [1m0.691163073185545[22m                ]8;id=523481;file://C:\Users\DELL\AppData\Roaming\Python\Python38\site-packages\openfl\component\collaborator\collaborator.py\collaborator.py]8;;\:]8;id=414850;file://C:\Users\DELL\AppData\Roaming\Python\Python38\site-packages\openfl\component\collaborator\collaborator.py#526\526]8;;\
           [34mINFO    [39m Waiting for global task completion[33m...[39m                                                                                    ]8;id=277746;file://C:\Users\DELL\AppData\Roaming\Python\Python38\site-packages\openfl\component\collaborator\collaborator.py\collaborator.py]8;;\:]8;id=146413;file://C:\Users\DELL\AppData\Roaming\Python\Python38\site-packages\openfl\component\collaborator\collaborator.py#355\355]8;;\
[13:24:57] [34mINFO    [39m Waiting for global task completion[33m...[39m                                                                                    ]8;id=275504;file://C:\Users\DELL\AppData\Roaming\Python\Python38\site-packages\openfl\component\collaborator\collaborator.py\collaborator.py]8;;\:]8;id=783300;file://C:\Users\DELL\AppData\Roaming\Python\Python38\site-packages\openfl\component\collaborator\collaborator.py#355\355]8;;\
           [34mINFO    [39m Using Interactive Python API                                                                                             ]8;id=418801;file://C:\Users\DELL\AppData\Roaming\Python\Python38\site-packages\openfl\component\collaborator\collaborator.py\collaborator.py]8;;\:]8;id=379580;file://C:\Users\DELL\AppData\Roaming\Python\Python38\site-packages\openfl\component\collaborator\collaborator.py#269\269]8;;\
min_times : 8
max_times :  285
min_times_1 :  8
max_times_1 :  235
[13:24:58] [1mERROR   [22m Collaborator failed with error: [1m0[22m:                                                                                               ]8;id=792495;file://C:\Users\DELL\AppData\Roaming\Python\Python38\site-packages\openfl\component\envoy\envoy.py\envoy.py]8;;\:]8;id=49405;file://C:\Users\DELL\AppData\Roaming\Python\Python38\site-packages\openfl\component\envoy\envoy.py#93\93]8;;\
                    Traceback [1m([22mmost recent call last[1m)[22m:
                      File [32m"C:\Users\DELL\anaconda3\envs\myenv\lib\site-packages\pandas\core\indexes\base.py"[39m, line [1m3802[22m, in get_loc
                        return [1mself._engine.get_loc([22mcasted_key[1m)
                      File [32m"pandas\_libs\index.pyx"[39m, line [1m138[22m, in pandas._libs.index.IndexEngine.get_loc
                      File [32m"pandas\_libs\index.pyx"[39m, line [1m165[22m, in pandas._libs.index.IndexEngine.get_loc
                      File [32m"pandas\_libs\hashtable_class_helper.pxi"[39m, line [1m2263[22m, in pandas._libs.hashtable.Int64HashTable.get_item
                      File [32m"pandas\_libs\hashtable_class_helper.pxi"[39m, line [1m2273[22m, in pandas._libs.hashtable.Int64HashTable.get_item
                    KeyError: [1m0
                    The above exception was the direct cause of the following exception:
                    Traceback [1m([22mmost recent call last[1m)[22m:
                      File [32m"C:\Users\DELL\AppData\Roaming\Python\Python38\site-packages\openfl\component\envoy\envoy.py"[39m, line [1m91[22m, in run
                        [1mself._run_collaborator()
                      File [32m"C:\Users\DELL\AppData\Roaming\Python\Python38\site-packages\openfl\component\envoy\envoy.py"[39m, line [1m164[22m, in
                    _run_collaborator
                        [1mcol.run()
                      File [32m"C:\Users\DELL\AppData\Roaming\Python\Python38\site-packages\openfl\component\collaborator\collaborator.py"[39m, line [1m174[22m, in
                    run
                        [1mself.do_task([22mtask, round_number[1m)
                      File [32m"C:\Users\DELL\AppData\Roaming\Python\Python38\site-packages\openfl\component\collaborator\collaborator.py"[39m, line [1m300[22m, in
                    do_task
                        global_output_tensor_dict, local_output_tensor_dict, optional = [1mfunc(
                      File [32m"C:\Users\DELL\AppData\Roaming\Python\Python38\site-packages\openfl\federated\task\runner_generic.py"[39m, line [1m79[22m, in
                    collaborator_adapted_task
                        metric_dict = [1mcallable_task([22m**task_kwargs[1m)
                      File [32m"C:\Users\DELL\AppData\Roaming\Python\Python38\site-packages\openfl\interface\interactive_api\experiment.py"[39m, line [1m512[22m,
                    in wrapper_decorator
                        metric_dict = [1mtraining_method([22m**task_keywords[1m)
                      File [32m"AdaBoostF_Heart_Failure.py"[39m, line [1m126[22m, in validate_weak_learners
                      File [32m"C:\Users\DELL\anaconda3\envs\myenv\lib\site-packages\pandas\core\series.py"[39m, line [1m981[22m, in __getitem__
                        return [1mself._get_value([22mkey[1m)
                      File [32m"C:\Users\DELL\anaconda3\envs\myenv\lib\site-packages\pandas\core\series.py"[39m, line [1m1089[22m, in _get_value
                        loc = [1mself.index.get_loc([22mlabel[1m)
                      File [32m"C:\Users\DELL\anaconda3\envs\myenv\lib\site-packages\pandas\core\indexes\base.py"[39m, line [1m3804[22m, in get_loc
                        raise [1mKeyError([22mkey[1m)[22m from err
                    KeyError: [1m0
           [34mINFO    [39m Send WaitExperiment request                                                                                            ]8;id=167753;file://C:\Users\DELL\AppData\Roaming\Python\Python38\site-packages\openfl\transport\grpc\director_client.py\director_client.py]8;;\:]8;id=830555;file://C:\Users\DELL\AppData\Roaming\Python\Python38\site-packages\openfl\transport\grpc\director_client.py#81\81]8;;\
